Workbook

Sheet IPS
A1: Player Name | B1: Position | C1: Total Score | D1: Akasia | E1: PGC | F1: Kyalami | G1: Copperleaf | H1: Services | I1: Column5 | J1: Column6 | K1: Column7 | L1: Names | M1: LIV Team | N1: ByNaam
A2: Arno Adonis | B2: 1 | C2: =SUM(D2:K2) -> 139 | D2: =IFERROR(VLOOKUP(Table2[[#This Row],[Player Name]],Akasia!$A$2:$C$23,3,FALSE),0) -> 36 | E2: =IFERROR(VLOOKUP(A2,Table58[[Name]:[IPS]],3,FALSE),0) -> 32 | F2: =IFERROR(VLOOKUP(A2,Table585[],3,FALSE),0) -> 37 | G2: =IFERROR(VLOOKUP(Table2[[#This Row],[Player Name]],Table58549[[#All],[Name]:[IPS]],3,FALSE),0) -> 34 | H2: =IFERROR(VLOOKUP(A2,#REF!,3,FALSE),0) -> 0 | I2: =IFERROR(VLOOKUP(Table2[[#This Row],[Names]],[1]!Scores_Strokes[#Data],5,FALSE),0) -> 0 | J2: =IFERROR(VLOOKUP(Table2[[#This Row],[Names]],[2]!Scores_Strokes[#Data],5,FALSE),0) -> 0 | K2: =IFERROR(VLOOKUP(Table2[[#This Row],[Names]],[3]!Scores_Strokes[#Data],5,FALSE),0) -> 0 | L2: Arno | M2: Home Boys | N2: Arno
A3: Lucien Barnes | B3: 2 | C3: =SUM(D3:K3) -> 132 | D3: =IFERROR(VLOOKUP(Table2[[#This Row],[Player Name]],Akasia!$A$2:$C$23,3,FALSE),0) -> 35 | E3: =IFERROR(VLOOKUP(A3,Table58[[Name]:[IPS]],3,FALSE),0) -> 32 | F3: =IFERROR(VLOOKUP(A3,Table585[],3,FALSE),0) -> 35 | G3: =IFERROR(VLOOKUP(Table2[[#This Row],[Player Name]],Table58549[[#All],[Name]:[IPS]],3,FALSE),0) -> 30 | H3: =IFERROR(VLOOKUP(A3,#REF!,3,FALSE),0) -> 0 | I3: =IFERROR(VLOOKUP(Table2[[#This Row],[Names]],[1]!Scores_Strokes[#Data],5,FALSE),0) -> 0 | J3: =IFERROR(VLOOKUP(Table2[[#This Row],[Names]],[2]!Scores_Strokes[#Data],5,FALSE),0) -> 0 | K3: =IFERROR(VLOOKUP(Table2[[#This Row],[Names]],[3]!Scores_Strokes[#Data],5,FALSE),0) -> 0 | L3: Lucien | M3: Fairway Fighters | N3: Lucien
A4: Mika Moerat | B4: 3 | C4: =SUM(D4:K4) -> 125 | D4: =IFERROR(VLOOKUP(Table2[[#This Row],[Player Name]],Akasia!$A$2:$C$23,3,FALSE),0) -> 33 | E4: =IFERROR(VLOOKUP(A4,Table58[[Name]:[IPS]],3,FALSE),0) -> 35 | F4: =IFERROR(VLOOKUP(A4,Table585[],3,FALSE),0) -> 29 | G4: =IFERROR(VLOOKUP(Table2[[#This Row],[Player Name]],Table58549[[#All],[Name]:[IPS]],3,FALSE),0) -> 28 | H4: =IFERROR(VLOOKUP(A4,#REF!,3,FALSE),0) -> 0 | I4: =IFERROR(VLOOKUP(Table2[[#This Row],[Names]],[1]!Scores_Strokes[#Data],5,FALSE),0) -> 0 | J4: =IFERROR(VLOOKUP(Table2[[#This Row],[Names]],[2]!Scores_Strokes[#Data],5,FALSE),0) -> 0 | K4: =IFERROR(VLOOKUP(Table2[[#This Row],[Names]],[3]!Scores_Strokes[#Data],5,FALSE),0) -> 0 | L4: Mika | M4: Fairway Fighters | N4: Mika
A5: Jodi Van Niekerk | B5: 4 | C5: =SUM(D5:K5) -> 117 | D5: =IFERROR(VLOOKUP(Table2[[#This Row],[Player Name]],Akasia!$A$2:$C$23,3,FALSE),0) -> 35 | E5: =IFERROR(VLOOKUP(A5,Table58[[Name]:[IPS]],3,FALSE),0) -> 31 | F5: =IFERROR(VLOOKUP(A5,Table585[],3,FALSE),0) -> 27 | G5: =IFERROR(VLOOKUP(Table2[[#This Row],[Player Name]],Table58549[[#All],[Name]:[IPS]],3,FALSE),0) -> 24 | H5: =IFERROR(VLOOKUP(A5,#REF!,3,FALSE),0) -> 0 | I5: =IFERROR(VLOOKUP(Table2[[#This Row],[Names]],[1]!Scores_Strokes[#Data],5,FALSE),0) -> 0 | J5: =IFERROR(VLOOKUP(Table2[[#This Row],[Names]],[2]!Scores_Strokes[#Data],5,FALSE),0) -> 0 | K5: =IFERROR(VLOOKUP(Table2[[#This Row],[Names]],[3]!Scores_Strokes[#Data],5,FALSE),0) -> 0 | L5: Jodi | M5: Tee Stingers | N5: Jodi
A6: Warren Lottering | B6: 5 | C6: =SUM(D6:K6) -> 95 | D6: =IFERROR(VLOOKUP(Table2[[#This Row],[Player Name]],Akasia!$A$2:$C$23,3,FALSE),0) -> 33 | E6: =IFERROR(VLOOKUP(A6,Table58[[Name]:[IPS]],3,FALSE),0) -> 26 | F6: =IFERROR(VLOOKUP(A6,Table585[],3,FALSE),0) -> 36 | G6: =IFERROR(VLOOKUP(Table2[[#This Row],[Player Name]],Table58549[[#All],[Name]:[IPS]],3,FALSE),0) -> 0 | H6: =IFERROR(VLOOKUP(A6,#REF!,3,FALSE),0) -> 0 | I6: =IFERROR(VLOOKUP(Table2[[#This Row],[Names]],[1]!Scores_Strokes[#Data],5,FALSE),0) -> 0 | J6: =IFERROR(VLOOKUP(Table2[[#This Row],[Names]],[2]!Scores_Strokes[#Data],5,FALSE),0) -> 0 | K6: =IFERROR(VLOOKUP(Table2[[#This Row],[Names]],[3]!Scores_Strokes[#Data],5,FALSE),0) -> 0 | L6: Warren | M6: Tee Stingers | N6: Warren
A7: Ranzel Louw | B7: 6 | C7: =SUM(D7:K7) -> 92 | D7: =IFERROR(VLOOKUP(Table2[[#This Row],[Player Name]],Akasia!$A$2:$C$23,3,FALSE),0) -> 25 | E7: =IFERROR(VLOOKUP(A7,Table58[[Name]:[IPS]],3,FALSE),0) -> 22 | F7: =IFERROR(VLOOKUP(A7,Table585[],3,FALSE),0) -> 29 | G7: =IFERROR(VLOOKUP(Table2[[#This Row],[Player Name]],Table58549[[#All],[Name]:[IPS]],3,FALSE),0) -> 16 | H7: =IFERROR(VLOOKUP(A7,#REF!,3,FALSE),0) -> 0 | I7: =IFERROR(VLOOKUP(Table2[[#This Row],[Names]],[1]!Scores_Strokes[#Data],5,FALSE),0) -> 0 | J7: =IFERROR(VLOOKUP(Table2[[#This Row],[Names]],[2]!Scores_Strokes[#Data],5,FALSE),0) -> 0 | K7: =IFERROR(VLOOKUP(Table2[[#This Row],[Names]],[3]!Scores_Strokes[#Data],5,FALSE),0) -> 0 | L7: Ranzel | M7: Tee Tigers | N7: Ranzel
A8: Trevor Meyer | B8: 7 | C8: =SUM(D8:K8) -> 88 | D8: =IFERROR(VLOOKUP(Table2[[#This Row],[Player Name]],Akasia!$A$2:$C$23,3,FALSE),0) -> 40 | E8: =IFERROR(VLOOKUP(A8,Table58[[Name]:[IPS]],3,FALSE),0) -> 30 | F8: =IFERROR(VLOOKUP(A8,Table585[],3,FALSE),0) -> 0 | G8: =IFERROR(VLOOKUP(Table2[[#This Row],[Player Name]],Table58549[[#All],[Name]:[IPS]],3,FALSE),0) -> 18 | H8: =IFERROR(VLOOKUP(A8,#REF!,3,FALSE),0) -> 0 | I8: =IFERROR(VLOOKUP(Table2[[#This Row],[Names]],[1]!Scores_Strokes[#Data],5,FALSE),0) -> 0 | J8: =IFERROR(VLOOKUP(Table2[[#This Row],[Names]],[2]!Scores_Strokes[#Data],5,FALSE),0) -> 0 | K8: =IFERROR(VLOOKUP(Table2[[#This Row],[Names]],[3]!Scores_Strokes[#Data],5,FALSE),0) -> 0 | L8: Uncle Trevor | M8: Fairway Fighters | N8: Trevor
A9: Dale Adonis | B9: 8 | C9: =SUM(D9:K9) -> 85 | D9: =IFERROR(VLOOKUP(Table2[[#This Row],[Player Name]],Akasia!$A$2:$C$23,3,FALSE),0) -> 32 | E9: =IFERROR(VLOOKUP(A9,Table58[[Name]:[IPS]],3,FALSE),0) -> 27 | F9: =IFERROR(VLOOKUP(A9,Table585[],3,FALSE),0) -> 0 | G9: =IFERROR(VLOOKUP(Table2[[#This Row],[Player Name]],Table58549[[#All],[Name]:[IPS]],3,FALSE),0) -> 26 | H9: =IFERROR(VLOOKUP(A9,#REF!,3,FALSE),0) -> 0 | I9: =IFERROR(VLOOKUP(Table2[[#This Row],[Names]],[1]!Scores_Strokes[#Data],5,FALSE),0) -> 0 | J9: =IFERROR(VLOOKUP(Table2[[#This Row],[Names]],[2]!Scores_Strokes[#Data],5,FALSE),0) -> 0 | K9: =IFERROR(VLOOKUP(Table2[[#This Row],[Names]],[3]!Scores_Strokes[#Data],5,FALSE),0) -> 0 | L9: Dale | M9: Home Boys | N9: Dale
A10: Ashley Spocter | B10: 9 | C10: =SUM(D10:K10) -> 82 | D10: =IFERROR(VLOOKUP(Table2[[#This Row],[Player Name]],Akasia!$A$2:$C$23,3,FALSE),0) -> 35 | E10: =IFERROR(VLOOKUP(A10,Table58[[Name]:[IPS]],3,FALSE),0) -> 23 | F10: =IFERROR(VLOOKUP(A10,Table585[],3,FALSE),0) -> 24 | G10: =IFERROR(VLOOKUP(Table2[[#This Row],[Player Name]],Table58549[[#All],[Name]:[IPS]],3,FALSE),0) -> 0 | H10: =IFERROR(VLOOKUP(A10,#REF!,3,FALSE),0) -> 0 | I10: =IFERROR(VLOOKUP(Table2[[#This Row],[Names]],[1]!Scores_Strokes[#Data],5,FALSE),0) -> 0 | J10: =IFERROR(VLOOKUP(Table2[[#This Row],[Names]],[2]!Scores_Strokes[#Data],5,FALSE),0) -> 0 | K10: =IFERROR(VLOOKUP(Table2[[#This Row],[Names]],[3]!Scores_Strokes[#Data],5,FALSE),0) -> 0 | L10: Ashley | M10: Tee Tigers | N10: Ash
A11: Byron Labuschagne | C11: =SUM(D11:K11) -> 82 | D11: =IFERROR(VLOOKUP(Table2[[#This Row],[Player Name]],Akasia!$A$2:$C$23,3,FALSE),0) -> 29 | E11: =IFERROR(VLOOKUP(A11,Table58[[Name]:[IPS]],3,FALSE),0) -> 28 | F11: =IFERROR(VLOOKUP(A11,Table585[],3,FALSE),0) -> 25 | G11: =IFERROR(VLOOKUP(Table2[[#This Row],[Player Name]],Table58549[[#All],[Name]:[IPS]],3,FALSE),0) -> 0 | H11: =IFERROR(VLOOKUP(A11,#REF!,3,FALSE),0) -> 0 | I11: =IFERROR(VLOOKUP(Table2[[#This Row],[Names]],[1]!Scores_Strokes[#Data],5,FALSE),0) -> 0 | J11: =IFERROR(VLOOKUP(Table2[[#This Row],[Names]],[2]!Scores_Strokes[#Data],5,FALSE),0) -> 0 | K11: =IFERROR(VLOOKUP(Table2[[#This Row],[Names]],[3]!Scores_Strokes[#Data],5,FALSE),0) -> 0 | L11: Byron | M11: Birdie Buddies | N11: Byrone
A12: Eugene Dudley | B12: 11 | C12: =SUM(D12:K12) -> 81 | D12: =IFERROR(VLOOKUP(Table2[[#This Row],[Player Name]],Akasia!$A$2:$C$23,3,FALSE),0) -> 30 | E12: =IFERROR(VLOOKUP(A12,Table58[[Name]:[IPS]],3,FALSE),0) -> 27 | F12: =IFERROR(VLOOKUP(A12,Table585[],3,FALSE),0) -> 0 | G12: =IFERROR(VLOOKUP(Table2[[#This Row],[Player Name]],Table58549[[#All],[Name]:[IPS]],3,FALSE),0) -> 24 | H12: =IFERROR(VLOOKUP(A12,#REF!,3,FALSE),0) -> 0 | I12: =IFERROR(VLOOKUP(Table2[[#This Row],[Names]],[1]!Scores_Strokes[#Data],5,FALSE),0) -> 0 | J12: =IFERROR(VLOOKUP(Table2[[#This Row],[Names]],[2]!Scores_Strokes[#Data],5,FALSE),0) -> 0 | K12: =IFERROR(VLOOKUP(Table2[[#This Row],[Names]],[3]!Scores_Strokes[#Data],5,FALSE),0) -> 0 | L12: Eugene | M12: Home Boys | N12: Eugene
A13: Shaheen Boughan | B13: 12 | C13: =SUM(D13:K13) -> 80 | D13: =IFERROR(VLOOKUP(Table2[[#This Row],[Player Name]],Akasia!$A$2:$C$23,3,FALSE),0) -> 28 | E13: =IFERROR(VLOOKUP(A13,Table58[[Name]:[IPS]],3,FALSE),0) -> 0 | F13: =IFERROR(VLOOKUP(A13,Table585[],3,FALSE),0) -> 28 | G13: =IFERROR(VLOOKUP(Table2[[#This Row],[Player Name]],Table58549[[#All],[Name]:[IPS]],3,FALSE),0) -> 24 | H13: =IFERROR(VLOOKUP(A13,#REF!,3,FALSE),0) -> 0 | I13: =IFERROR(VLOOKUP(Table2[[#This Row],[Names]],[1]!Scores_Strokes[#Data],5,FALSE),0) -> 0 | J13: =IFERROR(VLOOKUP(Table2[[#This Row],[Names]],[2]!Scores_Strokes[#Data],5,FALSE),0) -> 0 | K13: =IFERROR(VLOOKUP(Table2[[#This Row],[Names]],[3]!Scores_Strokes[#Data],5,FALSE),0) -> 0 | L13: Shaheen | M13: Birdie Buddies | N13: Shaheen
A14: John Barker | B14: 13 | C14: =SUM(D14:K14) -> 74 | D14: =IFERROR(VLOOKUP(Table2[[#This Row],[Player Name]],Akasia!$A$2:$C$23,3,FALSE),0) -> 36 | E14: =IFERROR(VLOOKUP(A14,Table58[[Name]:[IPS]],3,FALSE),0) -> 0 | F14: =IFERROR(VLOOKUP(A14,Table585[],3,FALSE),0) -> 0 | G14: =IFERROR(VLOOKUP(Table2[[#This Row],[Player Name]],Table58549[[#All],[Name]:[IPS]],3,FALSE),0) -> 38 | H14: =IFERROR(VLOOKUP(A14,#REF!,3,FALSE),0) -> 0 | I14: =IFERROR(VLOOKUP(Table2[[#This Row],[Names]],[1]!Scores_Strokes[#Data],5,FALSE),0) -> 0 | J14: =IFERROR(VLOOKUP(Table2[[#This Row],[Names]],[2]!Scores_Strokes[#Data],5,FALSE),0) -> 0 | K14: =IFERROR(VLOOKUP(Table2[[#This Row],[Names]],[3]!Scores_Strokes[#Data],5,FALSE),0) -> 0 | L14: Uncle John | M14: Tee Tigers | N14: John
A15: Laurent Changuion | B15: 14 | C15: =SUM(D15:K15) -> 73 | D15: =IFERROR(VLOOKUP(Table2[[#This Row],[Player Name]],Akasia!$A$2:$C$23,3,FALSE),0) -> 19 | E15: =IFERROR(VLOOKUP(A15,Table58[[Name]:[IPS]],3,FALSE),0) -> 29 | F15: =IFERROR(VLOOKUP(A15,Table585[],3,FALSE),0) -> 0 | G15: =IFERROR(VLOOKUP(Table2[[#This Row],[Player Name]],Table58549[[#All],[Name]:[IPS]],3,FALSE),0) -> 25 | H15: =IFERROR(VLOOKUP(A15,#REF!,3,FALSE),0) -> 0 | I15: =IFERROR(VLOOKUP(Table2[[#This Row],[Names]],[1]!Scores_Strokes[#Data],5,FALSE),0) -> 0 | J15: =IFERROR(VLOOKUP(Table2[[#This Row],[Names]],[2]!Scores_Strokes[#Data],5,FALSE),0) -> 0 | K15: =IFERROR(VLOOKUP(Table2[[#This Row],[Names]],[3]!Scores_Strokes[#Data],5,FALSE),0) -> 0 | L15: Laurent | M15: Tee Stingers | N15: ⁠Laurent
A16: Chad Naude | B16: 15 | C16: =SUM(D16:K16) -> 72 | D16: =IFERROR(VLOOKUP(Table2[[#This Row],[Player Name]],Akasia!$A$2:$C$23,3,FALSE),0) -> 0 | E16: =IFERROR(VLOOKUP(A16,Table58[[Name]:[IPS]],3,FALSE),0) -> 35 | F16: =IFERROR(VLOOKUP(A16,Table585[],3,FALSE),0) -> 37 | G16: =IFERROR(VLOOKUP(Table2[[#This Row],[Player Name]],Table58549[[#All],[Name]:[IPS]],3,FALSE),0) -> 0 | H16: =IFERROR(VLOOKUP(A16,#REF!,3,FALSE),0) -> 0 | I16: =IFERROR(VLOOKUP(Table2[[#This Row],[Names]],[1]!Scores_Strokes[#Data],5,FALSE),0) -> 0 | J16: =IFERROR(VLOOKUP(Table2[[#This Row],[Names]],[2]!Scores_Strokes[#Data],5,FALSE),0) -> 0 | K16: =IFERROR(VLOOKUP(Table2[[#This Row],[Names]],[3]!Scores_Strokes[#Data],5,FALSE),0) -> 0 | L16: Chad | M16: Fairway Fighters | N16: Chad
A17: Bjorn Singh | B17: 16 | C17: =SUM(D17:K17) -> 69 | D17: =IFERROR(VLOOKUP(Table2[[#This Row],[Player Name]],Akasia!$A$2:$C$23,3,FALSE),0) -> 0 | E17: =IFERROR(VLOOKUP(A17,Table58[[Name]:[IPS]],3,FALSE),0) -> 35 | F17: =IFERROR(VLOOKUP(A17,Table585[],3,FALSE),0) -> 34 | G17: =IFERROR(VLOOKUP(Table2[[#This Row],[Player Name]],Table58549[[#All],[Name]:[IPS]],3,FALSE),0) -> 0 | H17: =IFERROR(VLOOKUP(A17,#REF!,3,FALSE),0) -> 0 | I17: =IFERROR(VLOOKUP(Table2[[#This Row],[Names]],[1]!Scores_Strokes[#Data],5,FALSE),0) -> 0 | J17: =IFERROR(VLOOKUP(Table2[[#This Row],[Names]],[2]!Scores_Strokes[#Data],5,FALSE),0) -> 0 | K17: =IFERROR(VLOOKUP(Table2[[#This Row],[Names]],[3]!Scores_Strokes[#Data],5,FALSE),0) -> 0 | L17: Bjorn | M17: Birdie Buddies | N17: Bjorn
A18: Winston Willemse | B18: 17 | C18: =SUM(D18:K18) -> 68 | D18: =IFERROR(VLOOKUP(Table2[[#This Row],[Player Name]],Akasia!$A$2:$C$23,3,FALSE),0) -> 36 | E18: =IFERROR(VLOOKUP(A18,Table58[[Name]:[IPS]],3,FALSE),0) -> 0 | F18: =IFERROR(VLOOKUP(A18,Table585[],3,FALSE),0) -> 0 | G18: =IFERROR(VLOOKUP(Table2[[#This Row],[Player Name]],Table58549[[#All],[Name]:[IPS]],3,FALSE),0) -> 32 | H18: =IFERROR(VLOOKUP(A18,#REF!,3,FALSE),0) -> 0 | I18: =IFERROR(VLOOKUP(Table2[[#This Row],[Names]],[1]!Scores_Strokes[#Data],5,FALSE),0) -> 0 | J18: =IFERROR(VLOOKUP(Table2[[#This Row],[Names]],[2]!Scores_Strokes[#Data],5,FALSE),0) -> 0 | K18: =IFERROR(VLOOKUP(Table2[[#This Row],[Names]],[3]!Scores_Strokes[#Data],5,FALSE),0) -> 0 | L18: Winston | M18: Tee Stingers | N18: Winna
A19: Pieter Gagiano | B19: 18 | C19: =SUM(D19:K19) -> 66 | D19: =IFERROR(VLOOKUP(Table2[[#This Row],[Player Name]],Akasia!$A$2:$C$23,3,FALSE),0) -> 14 | E19: =IFERROR(VLOOKUP(A19,Table58[[Name]:[IPS]],3,FALSE),0) -> 22 | F19: =IFERROR(VLOOKUP(A19,Table585[],3,FALSE),0) -> 0 | G19: =IFERROR(VLOOKUP(Table2[[#This Row],[Player Name]],Table58549[[#All],[Name]:[IPS]],3,FALSE),0) -> 30 | H19: =IFERROR(VLOOKUP(A19,#REF!,3,FALSE),0) -> 0 | I19: =IFERROR(VLOOKUP(Table2[[#This Row],[Names]],[1]!Scores_Strokes[#Data],5,FALSE),0) -> 0 | J19: =IFERROR(VLOOKUP(Table2[[#This Row],[Names]],[2]!Scores_Strokes[#Data],5,FALSE),0) -> 0 | K19: =IFERROR(VLOOKUP(Table2[[#This Row],[Names]],[3]!Scores_Strokes[#Data],5,FALSE),0) -> 0 | L19: Pieter | M19: Tee Tigers | N19: Pieter
A20: Shawn Davies | B20: 19 | C20: =SUM(D20:K20) -> 63 | D20: =IFERROR(VLOOKUP(Table2[[#This Row],[Player Name]],Akasia!$A$2:$C$23,3,FALSE),0) -> 0 | E20: =IFERROR(VLOOKUP(A20,Table58[[Name]:[IPS]],3,FALSE),0) -> 31 | F20: =IFERROR(VLOOKUP(A20,Table585[],3,FALSE),0) -> 0 | G20: =IFERROR(VLOOKUP(Table2[[#This Row],[Player Name]],Table58549[[#All],[Name]:[IPS]],3,FALSE),0) -> 32 | H20: =IFERROR(VLOOKUP(A20,#REF!,3,FALSE),0) -> 0 | I20: =IFERROR(VLOOKUP(Table2[[#This Row],[Names]],[1]!Scores_Strokes[#Data],5,FALSE),0) -> 0 | J20: =IFERROR(VLOOKUP(Table2[[#This Row],[Names]],[2]!Scores_Strokes[#Data],5,FALSE),0) -> 0 | K20: =IFERROR(VLOOKUP(Table2[[#This Row],[Names]],[3]!Scores_Strokes[#Data],5,FALSE),0) -> 0 | L20: Shawn | M20: Birdie Buddies | N20: Shawn
A21: Dewald Van Rooyen | B21: 20 | C21: =SUM(D21:K21) -> 55 | D21: =IFERROR(VLOOKUP(Table2[[#This Row],[Player Name]],Akasia!$A$2:$C$23,3,FALSE),0) -> 24 | E21: =IFERROR(VLOOKUP(A21,Table58[[Name]:[IPS]],3,FALSE),0) -> 0 | F21: =IFERROR(VLOOKUP(A21,Table585[],3,FALSE),0) -> 31 | G21: =IFERROR(VLOOKUP(Table2[[#This Row],[Player Name]],Table58549[[#All],[Name]:[IPS]],3,FALSE),0) -> 0 | H21: =IFERROR(VLOOKUP(A21,#REF!,3,FALSE),0) -> 0 | I21: =IFERROR(VLOOKUP(Table2[[#This Row],[Names]],[1]!Scores_Strokes[#Data],5,FALSE),0) -> 0 | J21: =IFERROR(VLOOKUP(Table2[[#This Row],[Names]],[2]!Scores_Strokes[#Data],5,FALSE),0) -> 0 | K21: =IFERROR(VLOOKUP(Table2[[#This Row],[Names]],[3]!Scores_Strokes[#Data],5,FALSE),0) -> 0 | L21: Dewald | M21: Fairway Fighters | N21: Dewald
A22: Godfrey Daniels | B22: 21 | C22: =SUM(D22:K22) -> 51 | D22: =IFERROR(VLOOKUP(Table2[[#This Row],[Player Name]],Akasia!$A$2:$C$23,3,FALSE),0) -> 31 | E22: =IFERROR(VLOOKUP(A22,Table58[[Name]:[IPS]],3,FALSE),0) -> 20 | F22: =IFERROR(VLOOKUP(A22,Table585[],3,FALSE),0) -> 0 | G22: =IFERROR(VLOOKUP(Table2[[#This Row],[Player Name]],Table58549[[#All],[Name]:[IPS]],3,FALSE),0) -> 0 | H22: =IFERROR(VLOOKUP(A22,#REF!,3,FALSE),0) -> 0 | I22: =IFERROR(VLOOKUP(Table2[[#This Row],[Names]],[1]!Scores_Strokes[#Data],5,FALSE),0) -> 0 | J22: =IFERROR(VLOOKUP(Table2[[#This Row],[Names]],[2]!Scores_Strokes[#Data],5,FALSE),0) -> 0 | K22: =IFERROR(VLOOKUP(Table2[[#This Row],[Names]],[3]!Scores_Strokes[#Data],5,FALSE),0) -> 0 | L22: Godfrey | M22: Tee Tigers | N22: Godfrey
A23: Lenny Booysen | B23: 22 | C23: =SUM(D23:K23) -> 45 | D23: =IFERROR(VLOOKUP(Table2[[#This Row],[Player Name]],Akasia!$A$2:$C$23,3,FALSE),0) -> 15 | E23: =IFERROR(VLOOKUP(A23,Table58[[Name]:[IPS]],3,FALSE),0) -> 30 | F23: =IFERROR(VLOOKUP(A23,Table585[],3,FALSE),0) -> 0 | G23: =IFERROR(VLOOKUP(Table2[[#This Row],[Player Name]],Table58549[[#All],[Name]:[IPS]],3,FALSE),0) -> 0 | H23: =IFERROR(VLOOKUP(A23,#REF!,3,FALSE),0) -> 0 | I23: =IFERROR(VLOOKUP(Table2[[#This Row],[Names]],[1]!Scores_Strokes[#Data],5,FALSE),0) -> 0 | J23: =IFERROR(VLOOKUP(Table2[[#This Row],[Names]],[2]!Scores_Strokes[#Data],5,FALSE),0) -> 0 | K23: =IFERROR(VLOOKUP(Table2[[#This Row],[Names]],[3]!Scores_Strokes[#Data],5,FALSE),0) -> 0 | L23: Lenny | M23: Tee Tigers | N23: Lenny
A24: Fuad Adams | B24: 23 | C24: =SUM(D24:K24) -> 34 | D24: =IFERROR(VLOOKUP(Table2[[#This Row],[Player Name]],Akasia!$A$2:$C$23,3,FALSE),0) -> 34 | E24: =IFERROR(VLOOKUP(A24,Table58[[Name]:[IPS]],3,FALSE),0) -> 0 | F24: =IFERROR(VLOOKUP(A24,Table585[],3,FALSE),0) -> 0 | G24: =IFERROR(VLOOKUP(Table2[[#This Row],[Player Name]],Table58549[[#All],[Name]:[IPS]],3,FALSE),0) -> 0 | H24: =IFERROR(VLOOKUP(A24,#REF!,3,FALSE),0) -> 0 | I24: =IFERROR(VLOOKUP(Table2[[#This Row],[Names]],[1]!Scores_Strokes[#Data],5,FALSE),0) -> 0 | J24: =IFERROR(VLOOKUP(Table2[[#This Row],[Names]],[2]!Scores_Strokes[#Data],5,FALSE),0) -> 0 | K24: =IFERROR(VLOOKUP(Table2[[#This Row],[Names]],[3]!Scores_Strokes[#Data],5,FALSE),0) -> 0 | L24: Fuad | M24: Home Boys | N24: Fuad
A25: Ronny Kaptein | C25: =SUM(D25:K25) -> 34 | D25: =IFERROR(VLOOKUP(Table2[[#This Row],[Player Name]],Akasia!$A$2:$C$23,3,FALSE),0) -> 0 | E25: =IFERROR(VLOOKUP(A25,Table58[[Name]:[IPS]],3,FALSE),0) -> 0 | F25: =IFERROR(VLOOKUP(A25,Table585[],3,FALSE),0) -> 0 | G25: =IFERROR(VLOOKUP(Table2[[#This Row],[Player Name]],Table58549[[#All],[Name]:[IPS]],3,FALSE),0) -> 34 | H25: =IFERROR(VLOOKUP(A25,#REF!,3,FALSE),0) -> 0 | I25: =IFERROR(VLOOKUP(Table2[[#This Row],[Names]],[1]!Scores_Strokes[#Data],5,FALSE),0) -> 0 | J25: =IFERROR(VLOOKUP(Table2[[#This Row],[Names]],[2]!Scores_Strokes[#Data],5,FALSE),0) -> 0 | K25: =IFERROR(VLOOKUP(Table2[[#This Row],[Names]],[3]!Scores_Strokes[#Data],5,FALSE),0) -> 0 | L25: Ronny | M25: Tee Tigers | N25: Ronny
A26: Arn Smith | B26: 25 | C26: =SUM(D26:K26) -> 28 | D26: =IFERROR(VLOOKUP(Table2[[#This Row],[Player Name]],Akasia!$A$2:$C$23,3,FALSE),0) -> 28 | E26: =IFERROR(VLOOKUP(A26,Table58[[Name]:[IPS]],3,FALSE),0) -> 0 | F26: =IFERROR(VLOOKUP(A26,Table585[],3,FALSE),0) -> 0 | G26: =IFERROR(VLOOKUP(Table2[[#This Row],[Player Name]],Table58549[[#All],[Name]:[IPS]],3,FALSE),0) -> 0 | H26: =IFERROR(VLOOKUP(A26,#REF!,3,FALSE),0) -> 0 | I26: =IFERROR(VLOOKUP(Table2[[#This Row],[Names]],[1]!Scores_Strokes[#Data],5,FALSE),0) -> 0 | J26: =IFERROR(VLOOKUP(Table2[[#This Row],[Names]],[2]!Scores_Strokes[#Data],5,FALSE),0) -> 0 | K26: =IFERROR(VLOOKUP(Table2[[#This Row],[Names]],[3]!Scores_Strokes[#Data],5,FALSE),0) -> 0 | L26: Arn | M26: Home Boys | N26: Arn
A27: Brian Plaatjies | B27: 26 | C27: =SUM(D27:K27) -> 24 | D27: =IFERROR(VLOOKUP(Table2[[#This Row],[Player Name]],Akasia!$A$2:$C$23,3,FALSE),0) -> 24 | E27: =IFERROR(VLOOKUP(A27,Table58[[Name]:[IPS]],3,FALSE),0) -> 0 | F27: =IFERROR(VLOOKUP(A27,Table585[],3,FALSE),0) -> 0 | G27: =IFERROR(VLOOKUP(Table2[[#This Row],[Player Name]],Table58549[[#All],[Name]:[IPS]],3,FALSE),0) -> 0 | H27: =IFERROR(VLOOKUP(A27,#REF!,3,FALSE),0) -> 0 | I27: =IFERROR(VLOOKUP(Table2[[#This Row],[Names]],[1]!Scores_Strokes[#Data],5,FALSE),0) -> 0 | J27: =IFERROR(VLOOKUP(Table2[[#This Row],[Names]],[2]!Scores_Strokes[#Data],5,FALSE),0) -> 0 | K27: =IFERROR(VLOOKUP(Table2[[#This Row],[Names]],[3]!Scores_Strokes[#Data],5,FALSE),0) -> 0 | L27: Brian | M27: Tee Tigers | N27: Brian
A28: Kirsten Jacobs | B28: 27 | C28: =SUM(D28:K28) -> 23 | D28: =IFERROR(VLOOKUP(Table2[[#This Row],[Player Name]],Akasia!$A$2:$C$23,3,FALSE),0) -> 0 | E28: =IFERROR(VLOOKUP(A28,Table58[[Name]:[IPS]],3,FALSE),0) -> 23 | F28: =IFERROR(VLOOKUP(A28,Table585[],3,FALSE),0) -> 0 | G28: =IFERROR(VLOOKUP(Table2[[#This Row],[Player Name]],Table58549[[#All],[Name]:[IPS]],3,FALSE),0) -> 0 | H28: =IFERROR(VLOOKUP(A28,#REF!,3,FALSE),0) -> 0 | I28: =IFERROR(VLOOKUP(Table2[[#This Row],[Names]],[1]!Scores_Strokes[#Data],5,FALSE),0) -> 0 | J28: =IFERROR(VLOOKUP(Table2[[#This Row],[Names]],[2]!Scores_Strokes[#Data],5,FALSE),0) -> 0 | K28: =IFERROR(VLOOKUP(Table2[[#This Row],[Names]],[3]!Scores_Strokes[#Data],5,FALSE),0) -> 0 | L28: Kirsten | M28: Tee Tigers | N28: Kirsten

Sheet Strokes
A1: Player Name | B1: Position | C1: Total Strokes - Over/Under | D1: Akasia | E1: PGC | F1: Kyalami | G1: Copperleaf | H1: Column4 | I1: Column5 | J1: Column6 | K1: Column7 | L1: Names | M1: Games Played
A2: Arno Adonis | B2: 1 | C2: =SUM(D2:K2) -> 55 | D2: =IFERROR(VLOOKUP(Table27[[#This Row],[Player Name]],Akasia!$A$2:$C$23,2,FALSE),0)-72 -> 16 | E2: =_xlfn.LET(_xlpm.r,IFERROR(VLOOKUP(A2,Table58[[Name]:[IPS]],2,FALSE),0),IF(_xlpm.r = 0, 0, _xlpm.r-72)) -> 15 | F2: =_xlfn.LET(_xlpm.r,IFERROR(VLOOKUP(A2,Table585[#All],2,FALSE),0),IF(_xlpm.r = 0, 0, _xlpm.r-72)) -> 11 | G2: =_xlfn.LET(_xlpm.r,IFERROR(VLOOKUP(A2,Table58549[],2,FALSE),0),IF(_xlpm.r = 0, 0, _xlpm.r-72)) -> 13 | H2: =IFERROR(VLOOKUP(A2,#REF!,3,FALSE),0) -> 0 | I2: =IFERROR(VLOOKUP(Table27[[#This Row],[Names]],[1]!Scores_Strokes[#Data],5,FALSE),0) -> 0 | J2: =IFERROR(VLOOKUP(Table27[[#This Row],[Names]],[2]!Scores_Strokes[#Data],5,FALSE),0) -> 0 | K2: =IFERROR(VLOOKUP(Table27[[#This Row],[Names]],[3]!Scores_Strokes[#Data],5,FALSE),0) -> 0 | L2: Arno | M2: =(Table27[[#This Row],[Akasia]]>0)+(Table27[[#This Row],[PGC]]>0)+(Table27[[#This Row],[Kyalami]]>0)+(Table27[[#This Row],[Copperleaf]]>0) -> 4
A3: Mika Moerat | B3: 2 | C3: =SUM(D3:K3) -> 57 | D3: =IFERROR(VLOOKUP(Table27[[#This Row],[Player Name]],Akasia!$A$2:$C$23,2,FALSE),0)-72 -> 15 | E3: =_xlfn.LET(_xlpm.r,IFERROR(VLOOKUP(A3,Table58[[Name]:[IPS]],2,FALSE),0),IF(_xlpm.r = 0, 0, _xlpm.r-72)) -> 9 | F3: =_xlfn.LET(_xlpm.r,IFERROR(VLOOKUP(A3,Table585[#All],2,FALSE),0),IF(_xlpm.r = 0, 0, _xlpm.r-72)) -> 18 | G3: =_xlfn.LET(_xlpm.r,IFERROR(VLOOKUP(A3,Table58549[],2,FALSE),0),IF(_xlpm.r = 0, 0, _xlpm.r-72)) -> 15 | H3: =IFERROR(VLOOKUP(A3,#REF!,3,FALSE),0) -> 0 | I3: =IFERROR(VLOOKUP(Table27[[#This Row],[Names]],[1]!Scores_Strokes[#Data],5,FALSE),0) -> 0 | J3: =IFERROR(VLOOKUP(Table27[[#This Row],[Names]],[2]!Scores_Strokes[#Data],5,FALSE),0) -> 0 | K3: =IFERROR(VLOOKUP(Table27[[#This Row],[Names]],[3]!Scores_Strokes[#Data],5,FALSE),0) -> 0 | L3: Mika | M3: =(Table27[[#This Row],[Akasia]]>0)+(Table27[[#This Row],[PGC]]>0)+(Table27[[#This Row],[Kyalami]]>0)+(Table27[[#This Row],[Copperleaf]]>0) -> 4
A4: Jodi Van Niekerk | B4: 3 | C4: =SUM(D4:K4) -> 91 | D4: =IFERROR(VLOOKUP(Table27[[#This Row],[Player Name]],Akasia!$A$2:$C$23,2,FALSE),0)-72 -> 17 | E4: =_xlfn.LET(_xlpm.r,IFERROR(VLOOKUP(A4,Table58[[Name]:[IPS]],2,FALSE),0),IF(_xlpm.r = 0, 0, _xlpm.r-72)) -> 19 | F4: =_xlfn.LET(_xlpm.r,IFERROR(VLOOKUP(A4,Table585[#All],2,FALSE),0),IF(_xlpm.r = 0, 0, _xlpm.r-72)) -> 27 | G4: =_xlfn.LET(_xlpm.r,IFERROR(VLOOKUP(A4,Table58549[],2,FALSE),0),IF(_xlpm.r = 0, 0, _xlpm.r-72)) -> 28 | H4: =IFERROR(VLOOKUP(A4,#REF!,3,FALSE),0) -> 0 | I4: =IFERROR(VLOOKUP(Table27[[#This Row],[Names]],[1]!Scores_Strokes[#Data],5,FALSE),0) -> 0 | J4: =IFERROR(VLOOKUP(Table27[[#This Row],[Names]],[2]!Scores_Strokes[#Data],5,FALSE),0) -> 0 | K4: =IFERROR(VLOOKUP(Table27[[#This Row],[Names]],[3]!Scores_Strokes[#Data],5,FALSE),0) -> 0 | L4: Jodi | M4: =(Table27[[#This Row],[Akasia]]>0)+(Table27[[#This Row],[PGC]]>0)+(Table27[[#This Row],[Kyalami]]>0)+(Table27[[#This Row],[Copperleaf]]>0) -> 4
A5: Lucien Barnes | B5: 4 | C5: =SUM(D5:K5) -> 98 | D5: =IFERROR(VLOOKUP(Table27[[#This Row],[Player Name]],Akasia!$A$2:$C$23,2,FALSE),0)-72 -> 24 | E5: =_xlfn.LET(_xlpm.r,IFERROR(VLOOKUP(A5,Table58[[Name]:[IPS]],2,FALSE),0),IF(_xlpm.r = 0, 0, _xlpm.r-72)) -> 24 | F5: =_xlfn.LET(_xlpm.r,IFERROR(VLOOKUP(A5,Table585[#All],2,FALSE),0),IF(_xlpm.r = 0, 0, _xlpm.r-72)) -> 23 | G5: =_xlfn.LET(_xlpm.r,IFERROR(VLOOKUP(A5,Table58549[],2,FALSE),0),IF(_xlpm.r = 0, 0, _xlpm.r-72)) -> 27 | H5: =IFERROR(VLOOKUP(A5,#REF!,3,FALSE),0) -> 0 | I5: =IFERROR(VLOOKUP(Table27[[#This Row],[Names]],[1]!Scores_Strokes[#Data],5,FALSE),0) -> 0 | J5: =IFERROR(VLOOKUP(Table27[[#This Row],[Names]],[2]!Scores_Strokes[#Data],5,FALSE),0) -> 0 | K5: =IFERROR(VLOOKUP(Table27[[#This Row],[Names]],[3]!Scores_Strokes[#Data],5,FALSE),0) -> 0 | L5: Lucien | M5: =(Table27[[#This Row],[Akasia]]>0)+(Table27[[#This Row],[PGC]]>0)+(Table27[[#This Row],[Kyalami]]>0)+(Table27[[#This Row],[Copperleaf]]>0) -> 4
A6: Ranzel Louw | B6: 5 | C6: =SUM(D6:K6) -> 105 | D6: =IFERROR(VLOOKUP(Table27[[#This Row],[Player Name]],Akasia!$A$2:$C$23,2,FALSE),0)-72 -> 26 | E6: =_xlfn.LET(_xlpm.r,IFERROR(VLOOKUP(A6,Table58[[Name]:[IPS]],2,FALSE),0),IF(_xlpm.r = 0, 0, _xlpm.r-72)) -> 28 | F6: =_xlfn.LET(_xlpm.r,IFERROR(VLOOKUP(A6,Table585[#All],2,FALSE),0),IF(_xlpm.r = 0, 0, _xlpm.r-72)) -> 21 | G6: =_xlfn.LET(_xlpm.r,IFERROR(VLOOKUP(A6,Table58549[],2,FALSE),0),IF(_xlpm.r = 0, 0, _xlpm.r-72)) -> 30 | H6: =IFERROR(VLOOKUP(A6,#REF!,3,FALSE),0) -> 0 | I6: =IFERROR(VLOOKUP(Table27[[#This Row],[Names]],[1]!Scores_Strokes[#Data],5,FALSE),0) -> 0 | J6: =IFERROR(VLOOKUP(Table27[[#This Row],[Names]],[2]!Scores_Strokes[#Data],5,FALSE),0) -> 0 | K6: =IFERROR(VLOOKUP(Table27[[#This Row],[Names]],[3]!Scores_Strokes[#Data],5,FALSE),0) -> 0 | L6: Ranzel | M6: =(Table27[[#This Row],[Akasia]]>0)+(Table27[[#This Row],[PGC]]>0)+(Table27[[#This Row],[Kyalami]]>0)+(Table27[[#This Row],[Copperleaf]]>0) -> 4
A7: Byron Labuschagne | B7: 6 | C7: =SUM(D7:K7) -> 64 | D7: =IFERROR(VLOOKUP(Table27[[#This Row],[Player Name]],Akasia!$A$2:$C$23,2,FALSE),0)-72 -> 20 | E7: =_xlfn.LET(_xlpm.r,IFERROR(VLOOKUP(A7,Table58[[Name]:[IPS]],2,FALSE),0),IF(_xlpm.r = 0, 0, _xlpm.r-72)) -> 22 | F7: =_xlfn.LET(_xlpm.r,IFERROR(VLOOKUP(A7,Table585[#All],2,FALSE),0),IF(_xlpm.r = 0, 0, _xlpm.r-72)) -> 22 | G7: =_xlfn.LET(_xlpm.r,IFERROR(VLOOKUP(A7,Table58549[],2,FALSE),0),IF(_xlpm.r = 0, 0, _xlpm.r-72)) -> 0 | H7: =IFERROR(VLOOKUP(A7,#REF!,3,FALSE),0) -> 0 | I7: =IFERROR(VLOOKUP(Table27[[#This Row],[Names]],[1]!Scores_Strokes[#Data],5,FALSE),0) -> 0 | J7: =IFERROR(VLOOKUP(Table27[[#This Row],[Names]],[2]!Scores_Strokes[#Data],5,FALSE),0) -> 0 | K7: =IFERROR(VLOOKUP(Table27[[#This Row],[Names]],[3]!Scores_Strokes[#Data],5,FALSE),0) -> 0 | L7: Byron | M7: =(Table27[[#This Row],[Akasia]]>0)+(Table27[[#This Row],[PGC]]>0)+(Table27[[#This Row],[Kyalami]]>0)+(Table27[[#This Row],[Copperleaf]]>0) -> 3
A8: Dale Adonis | B8: 7 | C8: =SUM(D8:K8) -> 64 | D8: =IFERROR(VLOOKUP(Table27[[#This Row],[Player Name]],Akasia!$A$2:$C$23,2,FALSE),0)-72 -> 20 | E8: =_xlfn.LET(_xlpm.r,IFERROR(VLOOKUP(A8,Table58[[Name]:[IPS]],2,FALSE),0),IF(_xlpm.r = 0, 0, _xlpm.r-72)) -> 23 | F8: =_xlfn.LET(_xlpm.r,IFERROR(VLOOKUP(A8,Table585[#All],2,FALSE),0),IF(_xlpm.r = 0, 0, _xlpm.r-72)) -> 0 | G8: =_xlfn.LET(_xlpm.r,IFERROR(VLOOKUP(A8,Table58549[],2,FALSE),0),IF(_xlpm.r = 0, 0, _xlpm.r-72)) -> 21 | H8: =IFERROR(VLOOKUP(A8,#REF!,3,FALSE),0) -> 0 | I8: =IFERROR(VLOOKUP(Table27[[#This Row],[Names]],[1]!Scores_Strokes[#Data],5,FALSE),0) -> 0 | J8: =IFERROR(VLOOKUP(Table27[[#This Row],[Names]],[2]!Scores_Strokes[#Data],5,FALSE),0) -> 0 | K8: =IFERROR(VLOOKUP(Table27[[#This Row],[Names]],[3]!Scores_Strokes[#Data],5,FALSE),0) -> 0 | L8: Dale | M8: =(Table27[[#This Row],[Akasia]]>0)+(Table27[[#This Row],[PGC]]>0)+(Table27[[#This Row],[Kyalami]]>0)+(Table27[[#This Row],[Copperleaf]]>0) -> 3
A9: Laurent Changuion | B9: 8 | C9: =SUM(D9:K9) -> 66 | D9: =IFERROR(VLOOKUP(Table27[[#This Row],[Player Name]],Akasia!$A$2:$C$23,2,FALSE),0)-72 -> 27 | E9: =_xlfn.LET(_xlpm.r,IFERROR(VLOOKUP(A9,Table58[[Name]:[IPS]],2,FALSE),0),IF(_xlpm.r = 0, 0, _xlpm.r-72)) -> 21 | F9: =_xlfn.LET(_xlpm.r,IFERROR(VLOOKUP(A9,Table585[#All],2,FALSE),0),IF(_xlpm.r = 0, 0, _xlpm.r-72)) -> 0 | G9: =_xlfn.LET(_xlpm.r,IFERROR(VLOOKUP(A9,Table58549[],2,FALSE),0),IF(_xlpm.r = 0, 0, _xlpm.r-72)) -> 18 | H9: =IFERROR(VLOOKUP(A9,#REF!,3,FALSE),0) -> 0 | I9: =IFERROR(VLOOKUP(Table27[[#This Row],[Names]],[1]!Scores_Strokes[#Data],5,FALSE),0) -> 0 | J9: =IFERROR(VLOOKUP(Table27[[#This Row],[Names]],[2]!Scores_Strokes[#Data],5,FALSE),0) -> 0 | K9: =IFERROR(VLOOKUP(Table27[[#This Row],[Names]],[3]!Scores_Strokes[#Data],5,FALSE),0) -> 0 | L9: Laurent | M9: =(Table27[[#This Row],[Akasia]]>0)+(Table27[[#This Row],[PGC]]>0)+(Table27[[#This Row],[Kyalami]]>0)+(Table27[[#This Row],[Copperleaf]]>0) -> 3
A10: Shaheen Boughan | B10: 9 | C10: =SUM(D10:K10) -> 71 | D10: =IFERROR(VLOOKUP(Table27[[#This Row],[Player Name]],Akasia!$A$2:$C$23,2,FALSE),0)-72 -> 24 | E10: =_xlfn.LET(_xlpm.r,IFERROR(VLOOKUP(A10,Table58[[Name]:[IPS]],2,FALSE),0),IF(_xlpm.r = 0, 0, _xlpm.r-72)) -> 0 | F10: =_xlfn.LET(_xlpm.r,IFERROR(VLOOKUP(A10,Table585[#All],2,FALSE),0),IF(_xlpm.r = 0, 0, _xlpm.r-72)) -> 23 | G10: =_xlfn.LET(_xlpm.r,IFERROR(VLOOKUP(A10,Table58549[],2,FALSE),0),IF(_xlpm.r = 0, 0, _xlpm.r-72)) -> 24 | H10: =IFERROR(VLOOKUP(A10,#REF!,3,FALSE),0) -> 0 | I10: =IFERROR(VLOOKUP(Table27[[#This Row],[Names]],[1]!Scores_Strokes[#Data],5,FALSE),0) -> 0 | J10: =IFERROR(VLOOKUP(Table27[[#This Row],[Names]],[2]!Scores_Strokes[#Data],5,FALSE),0) -> 0 | K10: =IFERROR(VLOOKUP(Table27[[#This Row],[Names]],[3]!Scores_Strokes[#Data],5,FALSE),0) -> 0 | L10: Shaheen | M10: =(Table27[[#This Row],[Akasia]]>0)+(Table27[[#This Row],[PGC]]>0)+(Table27[[#This Row],[Kyalami]]>0)+(Table27[[#This Row],[Copperleaf]]>0) -> 3
A11: Warren Lottering | B11: 10 | C11: =SUM(D11:K11) -> 75 | D11: =IFERROR(VLOOKUP(Table27[[#This Row],[Player Name]],Akasia!$A$2:$C$23,2,FALSE),0)-72 -> 25 | E11: =_xlfn.LET(_xlpm.r,IFERROR(VLOOKUP(A11,Table58[[Name]:[IPS]],2,FALSE),0),IF(_xlpm.r = 0, 0, _xlpm.r-72)) -> 29 | F11: =_xlfn.LET(_xlpm.r,IFERROR(VLOOKUP(A11,Table585[#All],2,FALSE),0),IF(_xlpm.r = 0, 0, _xlpm.r-72)) -> 21 | G11: =_xlfn.LET(_xlpm.r,IFERROR(VLOOKUP(A11,Table58549[],2,FALSE),0),IF(_xlpm.r = 0, 0, _xlpm.r-72)) -> 0 | H11: =IFERROR(VLOOKUP(A11,#REF!,3,FALSE),0) -> 0 | I11: =IFERROR(VLOOKUP(Table27[[#This Row],[Names]],[1]!Scores_Strokes[#Data],5,FALSE),0) -> 0 | J11: =IFERROR(VLOOKUP(Table27[[#This Row],[Names]],[2]!Scores_Strokes[#Data],5,FALSE),0) -> 0 | K11: =IFERROR(VLOOKUP(Table27[[#This Row],[Names]],[3]!Scores_Strokes[#Data],5,FALSE),0) -> 0 | L11: Warren | M11: =(Table27[[#This Row],[Akasia]]>0)+(Table27[[#This Row],[PGC]]>0)+(Table27[[#This Row],[Kyalami]]>0)+(Table27[[#This Row],[Copperleaf]]>0) -> 3
A12: Trevor Meyer | B12: 11 | C12: =SUM(D12:K12) -> 79 | D12: =IFERROR(VLOOKUP(Table27[[#This Row],[Player Name]],Akasia!$A$2:$C$23,2,FALSE),0)-72 -> 18 | E12: =_xlfn.LET(_xlpm.r,IFERROR(VLOOKUP(A12,Table58[[Name]:[IPS]],2,FALSE),0),IF(_xlpm.r = 0, 0, _xlpm.r-72)) -> 23 | F12: =_xlfn.LET(_xlpm.r,IFERROR(VLOOKUP(A12,Table585[#All],2,FALSE),0),IF(_xlpm.r = 0, 0, _xlpm.r-72)) -> 0 | G12: =_xlfn.LET(_xlpm.r,IFERROR(VLOOKUP(A12,Table58549[],2,FALSE),0),IF(_xlpm.r = 0, 0, _xlpm.r-72)) -> 38 | H12: =IFERROR(VLOOKUP(A12,#REF!,3,FALSE),0) -> 0 | I12: =IFERROR(VLOOKUP(Table27[[#This Row],[Names]],[1]!Scores_Strokes[#Data],5,FALSE),0) -> 0 | J12: =IFERROR(VLOOKUP(Table27[[#This Row],[Names]],[2]!Scores_Strokes[#Data],5,FALSE),0) -> 0 | K12: =IFERROR(VLOOKUP(Table27[[#This Row],[Names]],[3]!Scores_Strokes[#Data],5,FALSE),0) -> 0 | L12: Uncle Trevor | M12: =(Table27[[#This Row],[Akasia]]>0)+(Table27[[#This Row],[PGC]]>0)+(Table27[[#This Row],[Kyalami]]>0)+(Table27[[#This Row],[Copperleaf]]>0) -> 3
A13: Ashley Spocter | B13: 12 | C13: =SUM(D13:K13) -> 83 | D13: =IFERROR(VLOOKUP(Table27[[#This Row],[Player Name]],Akasia!$A$2:$C$23,2,FALSE),0)-72 -> 21 | E13: =_xlfn.LET(_xlpm.r,IFERROR(VLOOKUP(A13,Table58[[Name]:[IPS]],2,FALSE),0),IF(_xlpm.r = 0, 0, _xlpm.r-72)) -> 30 | F13: =_xlfn.LET(_xlpm.r,IFERROR(VLOOKUP(A13,Table585[#All],2,FALSE),0),IF(_xlpm.r = 0, 0, _xlpm.r-72)) -> 32 | G13: =_xlfn.LET(_xlpm.r,IFERROR(VLOOKUP(A13,Table58549[],2,FALSE),0),IF(_xlpm.r = 0, 0, _xlpm.r-72)) -> 0 | H13: =IFERROR(VLOOKUP(A13,#REF!,3,FALSE),0) -> 0 | I13: =IFERROR(VLOOKUP(Table27[[#This Row],[Names]],[1]!Scores_Strokes[#Data],5,FALSE),0) -> 0 | J13: =IFERROR(VLOOKUP(Table27[[#This Row],[Names]],[2]!Scores_Strokes[#Data],5,FALSE),0) -> 0 | K13: =IFERROR(VLOOKUP(Table27[[#This Row],[Names]],[3]!Scores_Strokes[#Data],5,FALSE),0) -> 0 | L13: Ashley | M13: =(Table27[[#This Row],[Akasia]]>0)+(Table27[[#This Row],[PGC]]>0)+(Table27[[#This Row],[Kyalami]]>0)+(Table27[[#This Row],[Copperleaf]]>0) -> 3
... A15: Pieter Gagiano | B15: 14 | C15: =SUM(D15:K15) -> 123 | D15: =IFERROR(VLOOKUP(Table27[[#This Row],[Player Name]],Akasia!$A$2:$C$23,2,FALSE),0)-72 -> 40 | E15: =_xlfn.LET(_xlpm.r,IFERROR(VLOOKUP(A15,Table58[[Name]:[IPS]],2,FALSE),0),IF(_xlpm.r = 0, 0, _xlpm.r-72)) -> 43 | F15: =_xlfn.LET(_xlpm.r,IFERROR(VLOOKUP(A15,Table585[#All],2,FALSE),0),IF(_xlpm.r = 0, 0, _xlpm.r-72)) -> 0 | G15: =_xlfn.LET(_xlpm.r,IFERROR(VLOOKUP(A15,Table58549[],2,FALSE),0),IF(_xlpm.r = 0, 0, _xlpm.r-72)) -> 40 | H15: =IFERROR(VLOOKUP(A15,#REF!,3,FALSE),0) -> 0 | I15: =IFERROR(VLOOKUP(Table27[[#This Row],[Names]],[1]!Scores_Strokes[#Data],5,FALSE),0) -> 0 | J15: =IFERROR(VLOOKUP(Table27[[#This Row],[Names]],[2]!Scores_Strokes[#Data],5,FALSE),0) -> 0 | K15: =IFERROR(VLOOKUP(Table27[[#This Row],[Names]],[3]!Scores_Strokes[#Data],5,FALSE),0) -> 0 | L15: Pieter | M15: =(Table27[[#This Row],[Akasia]]>0)+(Table27[[#This Row],[PGC]]>0)+(Table27[[#This Row],[Kyalami]]>0)+(Table27[[#This Row],[Copperleaf]]>0) -> 3
A16: Shawn Davies | B16: 15 | C16: =SUM(D16:K16) -> 17 | D16: 0 | E16: =_xlfn.LET(_xlpm.r,IFERROR(VLOOKUP(A16,Table58[[Name]:[IPS]],2,FALSE),0),IF(_xlpm.r = 0, 0, _xlpm.r-72)) -> 10 | F16: =_xlfn.LET(_xlpm.r,IFERROR(VLOOKUP(A16,Table585[#All],2,FALSE),0),IF(_xlpm.r = 0, 0, _xlpm.r-72)) -> 0 | G16: =_xlfn.LET(_xlpm.r,IFERROR(VLOOKUP(A16,Table58549[],2,FALSE),0),IF(_xlpm.r = 0, 0, _xlpm.r-72)) -> 7 | H16: =IFERROR(VLOOKUP(A16,#REF!,3,FALSE),0) -> 0 | I16: =IFERROR(VLOOKUP(Table27[[#This Row],[Names]],[1]!Scores_Strokes[#Data],5,FALSE),0) -> 0 | J16: =IFERROR(VLOOKUP(Table27[[#This Row],[Names]],[2]!Scores_Strokes[#Data],5,FALSE),0) -> 0 | K16: =IFERROR(VLOOKUP(Table27[[#This Row],[Names]],[3]!Scores_Strokes[#Data],5,FALSE),0) -> 0 | L16: Shawn | M16: =(Table27[[#This Row],[Akasia]]>0)+(Table27[[#This Row],[PGC]]>0)+(Table27[[#This Row],[Kyalami]]>0)+(Table27[[#This Row],[Copperleaf]]>0) -> 2
A17: John Barker | B17: 16 | C17: =SUM(D17:K17) -> 22 | D17: =IFERROR(VLOOKUP(Table27[[#This Row],[Player Name]],Akasia!$A$2:$C$23,2,FALSE),0)-72 -> 14 | E17: =_xlfn.LET(_xlpm.r,IFERROR(VLOOKUP(A17,Table58[[Name]:[IPS]],2,FALSE),0),IF(_xlpm.r = 0, 0, _xlpm.r-72)) -> 0 | F17: =_xlfn.LET(_xlpm.r,IFERROR(VLOOKUP(A17,Table585[#All],2,FALSE),0),IF(_xlpm.r = 0, 0, _xlpm.r-72)) -> 0 | G17: =_xlfn.LET(_xlpm.r,IFERROR(VLOOKUP(A17,Table58549[],2,FALSE),0),IF(_xlpm.r = 0, 0, _xlpm.r-72)) -> 8 | H17: =IFERROR(VLOOKUP(A17,#REF!,3,FALSE),0) -> 0 | I17: =IFERROR(VLOOKUP(Table27[[#This Row],[Names]],[1]!Scores_Strokes[#Data],5,FALSE),0) -> 0 | J17: =IFERROR(VLOOKUP(Table27[[#This Row],[Names]],[2]!Scores_Strokes[#Data],5,FALSE),0) -> 0 | K17: =IFERROR(VLOOKUP(Table27[[#This Row],[Names]],[3]!Scores_Strokes[#Data],5,FALSE),0) -> 0 | L17: Uncle John | M17: =(Table27[[#This Row],[Akasia]]>0)+(Table27[[#This Row],[PGC]]>0)+(Table27[[#This Row],[Kyalami]]>0)+(Table27[[#This Row],[Copperleaf]]>0) -> 2
A18: Chad Naude | B18: 17 | C18: =SUM(D18:K18) -> 33 | D18: 0 | E18: =_xlfn.LET(_xlpm.r,IFERROR(VLOOKUP(A18,Table58[[Name]:[IPS]],2,FALSE),0),IF(_xlpm.r = 0, 0, _xlpm.r-72)) -> 15 | F18: =_xlfn.LET(_xlpm.r,IFERROR(VLOOKUP(A18,Table585[#All],2,FALSE),0),IF(_xlpm.r = 0, 0, _xlpm.r-72)) -> 18 | G18: =_xlfn.LET(_xlpm.r,IFERROR(VLOOKUP(A18,Table58549[],2,FALSE),0),IF(_xlpm.r = 0, 0, _xlpm.r-72)) -> 0 | H18: =IFERROR(VLOOKUP(A18,#REF!,3,FALSE),0) -> 0 | I18: =IFERROR(VLOOKUP(Table27[[#This Row],[Names]],[1]!Scores_Strokes[#Data],5,FALSE),0) -> 0 | J18: =IFERROR(VLOOKUP(Table27[[#This Row],[Names]],[2]!Scores_Strokes[#Data],5,FALSE),0) -> 0 | K18: =IFERROR(VLOOKUP(Table27[[#This Row],[Names]],[3]!Scores_Strokes[#Data],5,FALSE),0) -> 0 | L18: Chad | M18: =(Table27[[#This Row],[Akasia]]>0)+(Table27[[#This Row],[PGC]]>0)+(Table27[[#This Row],[Kyalami]]>0)+(Table27[[#This Row],[Copperleaf]]>0) -> 2
A19: Bjorn Singh | B19: 18 | C19: =SUM(D19:K19) -> 39 | D19: 0 | E19: =_xlfn.LET(_xlpm.r,IFERROR(VLOOKUP(A19,Table58[[Name]:[IPS]],2,FALSE),0),IF(_xlpm.r = 0, 0, _xlpm.r-72)) -> 18 | F19: =_xlfn.LET(_xlpm.r,IFERROR(VLOOKUP(A19,Table585[#All],2,FALSE),0),IF(_xlpm.r = 0, 0, _xlpm.r-72)) -> 21 | G19: =_xlfn.LET(_xlpm.r,IFERROR(VLOOKUP(A19,Table58549[],2,FALSE),0),IF(_xlpm.r = 0, 0, _xlpm.r-72)) -> 0 | H19: =IFERROR(VLOOKUP(A19,#REF!,3,FALSE),0) -> 0 | I19: =IFERROR(VLOOKUP(Table27[[#This Row],[Names]],[1]!Scores_Strokes[#Data],5,FALSE),0) -> 0 | J19: =IFERROR(VLOOKUP(Table27[[#This Row],[Names]],[2]!Scores_Strokes[#Data],5,FALSE),0) -> 0 | K19: =IFERROR(VLOOKUP(Table27[[#This Row],[Names]],[3]!Scores_Strokes[#Data],5,FALSE),0) -> 0 | L19: Bjorn | M19: =(Table27[[#This Row],[Akasia]]>0)+(Table27[[#This Row],[PGC]]>0)+(Table27[[#This Row],[Kyalami]]>0)+(Table27[[#This Row],[Copperleaf]]>0) -> 2
A20: Winston Willemse | B20: 19 | C20: =SUM(D20:K20) -> 41 | D20: =IFERROR(VLOOKUP(Table27[[#This Row],[Player Name]],Akasia!$A$2:$C$23,2,FALSE),0)-72 -> 19 | E20: =_xlfn.LET(_xlpm.r,IFERROR(VLOOKUP(A20,Table58[[Name]:[IPS]],2,FALSE),0),IF(_xlpm.r = 0, 0, _xlpm.r-72)) -> 0 | F20: =_xlfn.LET(_xlpm.r,IFERROR(VLOOKUP(A20,Table585[#All],2,FALSE),0),IF(_xlpm.r = 0, 0, _xlpm.r-72)) -> 0 | G20: =_xlfn.LET(_xlpm.r,IFERROR(VLOOKUP(A20,Table58549[],2,FALSE),0),IF(_xlpm.r = 0, 0, _xlpm.r-72)) -> 22 | H20: =IFERROR(VLOOKUP(A20,#REF!,3,FALSE),0) -> 0 | I20: =IFERROR(VLOOKUP(Table27[[#This Row],[Names]],[1]!Scores_Strokes[#Data],5,FALSE),0) -> 0 | J20: =IFERROR(VLOOKUP(Table27[[#This Row],[Names]],[2]!Scores_Strokes[#Data],5,FALSE),0) -> 0 | K20: =IFERROR(VLOOKUP(Table27[[#This Row],[Names]],[3]!Scores_Strokes[#Data],5,FALSE),0) -> 0 | L20: Winston | M20: =(Table27[[#This Row],[Akasia]]>0)+(Table27[[#This Row],[PGC]]>0)+(Table27[[#This Row],[Kyalami]]>0)+(Table27[[#This Row],[Copperleaf]]>0) -> 2
A21: Dewald Van Rooyen | B21: 20 | C21: =SUM(D21:K21) -> 48 | D21: =IFERROR(VLOOKUP(Table27[[#This Row],[Player Name]],Akasia!$A$2:$C$23,2,FALSE),0)-72 -> 26 | E21: =_xlfn.LET(_xlpm.r,IFERROR(VLOOKUP(A21,Table58[[Name]:[IPS]],2,FALSE),0),IF(_xlpm.r = 0, 0, _xlpm.r-72)) -> 0 | F21: =_xlfn.LET(_xlpm.r,IFERROR(VLOOKUP(A21,Table585[#All],2,FALSE),0),IF(_xlpm.r = 0, 0, _xlpm.r-72)) -> 22 | G21: =_xlfn.LET(_xlpm.r,IFERROR(VLOOKUP(A21,Table58549[],2,FALSE),0),IF(_xlpm.r = 0, 0, _xlpm.r-72)) -> 0 | H21: =IFERROR(VLOOKUP(A21,#REF!,3,FALSE),0) -> 0 | I21: =IFERROR(VLOOKUP(Table27[[#This Row],[Names]],[1]!Scores_Strokes[#Data],5,FALSE),0) -> 0 | J21: =IFERROR(VLOOKUP(Table27[[#This Row],[Names]],[2]!Scores_Strokes[#Data],5,FALSE),0) -> 0 | K21: =IFERROR(VLOOKUP(Table27[[#This Row],[Names]],[3]!Scores_Strokes[#Data],5,FALSE),0) -> 0 | L21: Dewald | M21: =(Table27[[#This Row],[Akasia]]>0)+(Table27[[#This Row],[PGC]]>0)+(Table27[[#This Row],[Kyalami]]>0)+(Table27[[#This Row],[Copperleaf]]>0) -> 2
A22: Godfrey Daniels | B22: 21 | C22: =SUM(D22:K22) -> 63 | D22: =IFERROR(VLOOKUP(Table27[[#This Row],[Player Name]],Akasia!$A$2:$C$23,2,FALSE),0)-72 -> 27 | E22: =_xlfn.LET(_xlpm.r,IFERROR(VLOOKUP(A22,Table58[[Name]:[IPS]],2,FALSE),0),IF(_xlpm.r = 0, 0, _xlpm.r-72)) -> 36 | F22: =_xlfn.LET(_xlpm.r,IFERROR(VLOOKUP(A22,Table585[#All],2,FALSE),0),IF(_xlpm.r = 0, 0, _xlpm.r-72)) -> 0 | G22: =_xlfn.LET(_xlpm.r,IFERROR(VLOOKUP(A22,Table58549[],2,FALSE),0),IF(_xlpm.r = 0, 0, _xlpm.r-72)) -> 0 | H22: =IFERROR(VLOOKUP(A22,#REF!,3,FALSE),0) -> 0 | I22: =IFERROR(VLOOKUP(Table27[[#This Row],[Names]],[1]!Scores_Strokes[#Data],5,FALSE),0) -> 0 | J22: =IFERROR(VLOOKUP(Table27[[#This Row],[Names]],[2]!Scores_Strokes[#Data],5,FALSE),0) -> 0 | K22: =IFERROR(VLOOKUP(Table27[[#This Row],[Names]],[3]!Scores_Strokes[#Data],5,FALSE),0) -> 0 | L22: Godfrey | M22: =(Table27[[#This Row],[Akasia]]>0)+(Table27[[#This Row],[PGC]]>0)+(Table27[[#This Row],[Kyalami]]>0)+(Table27[[#This Row],[Copperleaf]]>0) -> 2
A23: Lenny Booysen | B23: 22 | C23: =SUM(D23:K23) -> 74 | D23: =IFERROR(VLOOKUP(Table27[[#This Row],[Player Name]],Akasia!$A$2:$C$23,2,FALSE),0)-72 -> 40 | E23: =_xlfn.LET(_xlpm.r,IFERROR(VLOOKUP(A23,Table58[[Name]:[IPS]],2,FALSE),0),IF(_xlpm.r = 0, 0, _xlpm.r-72)) -> 34 | F23: =_xlfn.LET(_xlpm.r,IFERROR(VLOOKUP(A23,Table585[#All],2,FALSE),0),IF(_xlpm.r = 0, 0, _xlpm.r-72)) -> 0 | G23: =_xlfn.LET(_xlpm.r,IFERROR(VLOOKUP(A23,Table58549[],2,FALSE),0),IF(_xlpm.r = 0, 0, _xlpm.r-72)) -> 0 | H23: =IFERROR(VLOOKUP(A23,#REF!,3,FALSE),0) -> 0 | I23: =IFERROR(VLOOKUP(Table27[[#This Row],[Names]],[1]!Scores_Strokes[#Data],5,FALSE),0) -> 0 | J23: =IFERROR(VLOOKUP(Table27[[#This Row],[Names]],[2]!Scores_Strokes[#Data],5,FALSE),0) -> 0 | K23: =IFERROR(VLOOKUP(Table27[[#This Row],[Names]],[3]!Scores_Strokes[#Data],5,FALSE),0) -> 0 | L23: Lenny | M23: =(Table27[[#This Row],[Akasia]]>0)+(Table27[[#This Row],[PGC]]>0)+(Table27[[#This Row],[Kyalami]]>0)+(Table27[[#This Row],[Copperleaf]]>0) -> 2
A24: Ronny Kaptein | B24: 23 | C24: =SUM(D24:K24) -> 16 | D24: 0 | E24: =_xlfn.LET(_xlpm.r,IFERROR(VLOOKUP(A24,Table58[[Name]:[IPS]],2,FALSE),0),IF(_xlpm.r = 0, 0, _xlpm.r-72)) -> 0 | F24: =_xlfn.LET(_xlpm.r,IFERROR(VLOOKUP(A24,Table585[#All],2,FALSE),0),IF(_xlpm.r = 0, 0, _xlpm.r-72)) -> 0 | G24: =_xlfn.LET(_xlpm.r,IFERROR(VLOOKUP(A24,Table58549[],2,FALSE),0),IF(_xlpm.r = 0, 0, _xlpm.r-72)) -> 16 | H24: =IFERROR(VLOOKUP(A24,#REF!,3,FALSE),0) -> 0 | I24: =IFERROR(VLOOKUP(Table27[[#This Row],[Names]],[1]!Scores_Strokes[#Data],5,FALSE),0) -> 0 | J24: =IFERROR(VLOOKUP(Table27[[#This Row],[Names]],[2]!Scores_Strokes[#Data],5,FALSE),0) -> 0 | K24: =IFERROR(VLOOKUP(Table27[[#This Row],[Names]],[3]!Scores_Strokes[#Data],5,FALSE),0) -> 0 | L24: Ronny | M24: =(Table27[[#This Row],[Akasia]]>0)+(Table27[[#This Row],[PGC]]>0)+(Table27[[#This Row],[Kyalami]]>0)+(Table27[[#This Row],[Copperleaf]]>0) -> 1
A25: Fuad Adams | B25: 24 | C25: =SUM(D25:K25) -> 21 | D25: =IFERROR(VLOOKUP(Table27[[#This Row],[Player Name]],Akasia!$A$2:$C$23,2,FALSE),0)-72 -> 21 | E25: =_xlfn.LET(_xlpm.r,IFERROR(VLOOKUP(A25,Table58[[Name]:[IPS]],2,FALSE),0),IF(_xlpm.r = 0, 0, _xlpm.r-72)) -> 0 | F25: =_xlfn.LET(_xlpm.r,IFERROR(VLOOKUP(A25,Table585[#All],2,FALSE),0),IF(_xlpm.r = 0, 0, _xlpm.r-72)) -> 0 | G25: =_xlfn.LET(_xlpm.r,IFERROR(VLOOKUP(A25,Table58549[],2,FALSE),0),IF(_xlpm.r = 0, 0, _xlpm.r-72)) -> 0 | H25: =IFERROR(VLOOKUP(A25,#REF!,3,FALSE),0) -> 0 | I25: =IFERROR(VLOOKUP(Table27[[#This Row],[Names]],[1]!Scores_Strokes[#Data],5,FALSE),0) -> 0 | J25: =IFERROR(VLOOKUP(Table27[[#This Row],[Names]],[2]!Scores_Strokes[#Data],5,FALSE),0) -> 0 | K25: =IFERROR(VLOOKUP(Table27[[#This Row],[Names]],[3]!Scores_Strokes[#Data],5,FALSE),0) -> 0 | L25: Fuad | M25: =(Table27[[#This Row],[Akasia]]>0)+(Table27[[#This Row],[PGC]]>0)+(Table27[[#This Row],[Kyalami]]>0)+(Table27[[#This Row],[Copperleaf]]>0) -> 1
A26: Arn Smith | B26: 25 | C26: =SUM(D26:K26) -> 31 | D26: =IFERROR(VLOOKUP(Table27[[#This Row],[Player Name]],Akasia!$A$2:$C$23,2,FALSE),0)-72 -> 31 | E26: =_xlfn.LET(_xlpm.r,IFERROR(VLOOKUP(A26,Table58[[Name]:[IPS]],2,FALSE),0),IF(_xlpm.r = 0, 0, _xlpm.r-72)) -> 0 | F26: =_xlfn.LET(_xlpm.r,IFERROR(VLOOKUP(A26,Table585[#All],2,FALSE),0),IF(_xlpm.r = 0, 0, _xlpm.r-72)) -> 0 | G26: =_xlfn.LET(_xlpm.r,IFERROR(VLOOKUP(A26,Table58549[],2,FALSE),0),IF(_xlpm.r = 0, 0, _xlpm.r-72)) -> 0 | H26: =IFERROR(VLOOKUP(A26,#REF!,3,FALSE),0) -> 0 | I26: =IFERROR(VLOOKUP(Table27[[#This Row],[Names]],[1]!Scores_Strokes[#Data],5,FALSE),0) -> 0 | J26: =IFERROR(VLOOKUP(Table27[[#This Row],[Names]],[2]!Scores_Strokes[#Data],5,FALSE),0) -> 0 | K26: =IFERROR(VLOOKUP(Table27[[#This Row],[Names]],[3]!Scores_Strokes[#Data],5,FALSE),0) -> 0 | L26: Arno | M26: =(Table27[[#This Row],[Akasia]]>0)+(Table27[[#This Row],[PGC]]>0)+(Table27[[#This Row],[Kyalami]]>0)+(Table27[[#This Row],[Copperleaf]]>0) -> 1
A27: Kirsten Jacobs | B27: 26 | C27: =SUM(D27:K27) -> 31 | D27: 0 | E27: =_xlfn.LET(_xlpm.r,IFERROR(VLOOKUP(A27,Table58[[Name]:[IPS]],2,FALSE),0),IF(_xlpm.r = 0, 0, _xlpm.r-72)) -> 31 | F27: =_xlfn.LET(_xlpm.r,IFERROR(VLOOKUP(A27,Table585[#All],2,FALSE),0),IF(_xlpm.r = 0, 0, _xlpm.r-72)) -> 0 | G27: =_xlfn.LET(_xlpm.r,IFERROR(VLOOKUP(A27,Table58549[],2,FALSE),0),IF(_xlpm.r = 0, 0, _xlpm.r-72)) -> 0 | H27: =IFERROR(VLOOKUP(A27,#REF!,3,FALSE),0) -> 0 | I27: =IFERROR(VLOOKUP(Table27[[#This Row],[Names]],[1]!Scores_Strokes[#Data],5,FALSE),0) -> 0 | J27: =IFERROR(VLOOKUP(Table27[[#This Row],[Names]],[2]!Scores_Strokes[#Data],5,FALSE),0) -> 0 | K27: =IFERROR(VLOOKUP(Table27[[#This Row],[Names]],[3]!Scores_Strokes[#Data],5,FALSE),0) -> 0 | L27: Ronny | M27: =(Table27[[#This Row],[Akasia]]>0)+(Table27[[#This Row],[PGC]]>0)+(Table27[[#This Row],[Kyalami]]>0)+(Table27[[#This Row],[Copperleaf]]>0) -> 1
A28: Brian Plaatjies | B28: 27 | C28: =SUM(D28:K28) -> 33 | D28: =IFERROR(VLOOKUP(Table27[[#This Row],[Player Name]],Akasia!$A$2:$C$23,2,FALSE),0)-72 -> 33 | E28: =_xlfn.LET(_xlpm.r,IFERROR(VLOOKUP(A28,Table58[[Name]:[IPS]],2,FALSE),0),IF(_xlpm.r = 0, 0, _xlpm.r-72)) -> 0 | F28: =_xlfn.LET(_xlpm.r,IFERROR(VLOOKUP(A28,Table585[#All],2,FALSE),0),IF(_xlpm.r = 0, 0, _xlpm.r-72)) -> 0 | G28: =_xlfn.LET(_xlpm.r,IFERROR(VLOOKUP(A28,Table58549[],2,FALSE),0),IF(_xlpm.r = 0, 0, _xlpm.r-72)) -> 0 | H28: =IFERROR(VLOOKUP(A28,#REF!,3,FALSE),0) -> 0 | I28: =IFERROR(VLOOKUP(Table27[[#This Row],[Names]],[1]!Scores_Strokes[#Data],5,FALSE),0) -> 0 | J28: =IFERROR(VLOOKUP(Table27[[#This Row],[Names]],[2]!Scores_Strokes[#Data],5,FALSE),0) -> 0 | K28: =IFERROR(VLOOKUP(Table27[[#This Row],[Names]],[3]!Scores_Strokes[#Data],5,FALSE),0) -> 0 | L28: Brian | M28: =(Table27[[#This Row],[Akasia]]>0)+(Table27[[#This Row],[PGC]]>0)+(Table27[[#This Row],[Kyalami]]>0)+(Table27[[#This Row],[Copperleaf]]>0) -> 1

Sheet LIV
A1: Team | B1: Total | C1: Akasia | D1: PGC | E1: Kyalami | F1: CopperLeaf | G1: Services | H1: Column5 | I1: Column6 | J1: Column7 | K1: Pos
A2: Fairway Fighters | B2: =SUM(C2:J2) -> 389 | C2: {=SUM(_xlfn.TAKE(_xlfn._xlws.SORT(_xlfn._xlws.FILTER(Akasia!$C$2:$C$23,Akasia!$D$2:$D$23=A2), 1, -1), 3))} -> 108 | D2: {=SUM(_xlfn.TAKE(_xlfn._xlws.SORT(_xlfn._xlws.FILTER(PGC!$C$2:$C$25, PGC!$D$2:$D$25=A2), 1, -1), 3))} -> 102 | E2: {=SUM(_xlfn.TAKE(_xlfn._xlws.SORT(_xlfn._xlws.FILTER(Kyalami!$C$2:$C$13,Kyalami!$D$2:$D$13=A2), 1,-1), 3))} -> 103 | F2: {=SUM(_xlfn.TAKE(_xlfn._xlws.SORT(_xlfn._xlws.FILTER(CopperLeaf!$C$2:$C$16,CopperLeaf!$D$2:$D$16=A2), 1,-1), 3))} -> 76 | G2: {=SUM(_xlfn.TAKE(_xlfn._xlws.SORT(_xlfn._xlws.FILTER(Services!$A$2:$C$23,Services!$D$2:$D$23=A2), 1, TRUE), 3))} -> 0 | K2: 1
A3: Tee Stingers | B3: =SUM(C3:J3) -> 334 | C3: {=SUM(_xlfn.TAKE(_xlfn._xlws.SORT(_xlfn._xlws.FILTER(Akasia!$C$2:$C$23,Akasia!$D$2:$D$23=A3), 1, -1), 3))} -> 104 | D3: {=SUM(_xlfn.TAKE(_xlfn._xlws.SORT(_xlfn._xlws.FILTER(PGC!$C$2:$C$25, PGC!$D$2:$D$25=A3), 1, -1), 3))} -> 86 | E3: {=SUM(_xlfn.TAKE(_xlfn._xlws.SORT(_xlfn._xlws.FILTER(Kyalami!$C$2:$C$13,Kyalami!$D$2:$D$13=A3), 1,-1), 3))} -> 63 | F3: {=SUM(_xlfn.TAKE(_xlfn._xlws.SORT(_xlfn._xlws.FILTER(CopperLeaf!$C$2:$C$16,CopperLeaf!$D$2:$D$16=A3), 1,-1), 3))} -> 81 | G3: {=SUM(_xlfn.TAKE(_xlfn._xlws.SORT(_xlfn._xlws.FILTER(Services!$A$2:$C$23,Services!$D$2:$D$23=A3), 1, TRUE), 3))} -> 0 | K3: 2
A4: Home Boys | B4: =SUM(C4:J4) -> 309 | C4: {=SUM(_xlfn.TAKE(_xlfn._xlws.SORT(_xlfn._xlws.FILTER(Akasia!$C$2:$C$23,Akasia!$D$2:$D$23=A4), 1, -1), 3))} -> 102 | D4: {=SUM(_xlfn.TAKE(_xlfn._xlws.SORT(_xlfn._xlws.FILTER(PGC!$C$2:$C$25, PGC!$D$2:$D$25=A4), 1, -1), 3))} -> 86 | E4: {=SUM(_xlfn.TAKE(_xlfn._xlws.SORT(_xlfn._xlws.FILTER(Kyalami!$C$2:$C$13,Kyalami!$D$2:$D$13=A4), 1,-1), 3))} -> 37 | F4: {=SUM(_xlfn.TAKE(_xlfn._xlws.SORT(_xlfn._xlws.FILTER(CopperLeaf!$C$2:$C$16,CopperLeaf!$D$2:$D$16=A4), 1,-1), 3))} -> 84 | G4: {=SUM(_xlfn.TAKE(_xlfn._xlws.SORT(_xlfn._xlws.FILTER(Services!$A$2:$C$23,Services!$D$2:$D$23=A4), 1, TRUE), 3))} -> 0 | K4: 3
A5: Birdie Buddies | B5: =SUM(C5:J5) -> 294 | C5: {=SUM(_xlfn.TAKE(_xlfn._xlws.SORT(_xlfn._xlws.FILTER(Akasia!$C$2:$C$23,Akasia!$D$2:$D$23=A5), 1, -1), 3))} -> 57 | D5: {=SUM(_xlfn.TAKE(_xlfn._xlws.SORT(_xlfn._xlws.FILTER(PGC!$C$2:$C$25, PGC!$D$2:$D$25=A5), 1, -1), 3))} -> 94 | E5: {=SUM(_xlfn.TAKE(_xlfn._xlws.SORT(_xlfn._xlws.FILTER(Kyalami!$C$2:$C$13,Kyalami!$D$2:$D$13=A5), 1,-1), 3))} -> 87 | F5: {=SUM(_xlfn.TAKE(_xlfn._xlws.SORT(_xlfn._xlws.FILTER(CopperLeaf!$C$2:$C$16,CopperLeaf!$D$2:$D$16=A5), 1,-1), 3))} -> 56 | G5: {=SUM(_xlfn.TAKE(_xlfn._xlws.SORT(_xlfn._xlws.FILTER(Services!$A$2:$C$23,Services!$D$2:$D$23=A5), 1, TRUE), 3))} -> 0 | K5: 4
A6: Tee Tigers | B6: =SUM(C6:J6) -> 288 | C6: 186 | D6: 0 | E6: 0 | F6: {=SUM(_xlfn.TAKE(_xlfn._xlws.SORT(_xlfn._xlws.FILTER(CopperLeaf!$C$2:$C$16,CopperLeaf!$D$2:$D$16=A6), 1,-1), 3))} -> 102 | G6: {=SUM(_xlfn.TAKE(_xlfn._xlws.SORT(_xlfn._xlws.FILTER(Services!$A$2:$C$23,Services!$D$2:$D$23=A6), 1, TRUE), 3))} -> 0 | K6: 5
A7: Tigers | B7: 0 | C7: 0 | D7: 0 | E7: 0 | F7: 0 | G7: {=SUM(_xlfn.TAKE(_xlfn._xlws.SORT(_xlfn._xlws.FILTER(Services!$A$2:$C$23,Services!$D$2:$D$23=A7), 1, TRUE), 3))} -> #VALUE! | K7: 6
G11: SUM(TAKE(SORT(FILTER(Akasia!$A$2:$C$23,Akasia!$D$2:$D$23=A2), 1, TRUE), 3))
G12: SUM(TAKE(SORT(FILTER(PGC!$C$2:$C$25, PGC!$D$2:$D$25=A2), 1, TRUE), 3))
G13: SUM(TAKE(SORT(FILTER(Kyalami!$A$2:$C$23,Kyalami!$D$2:$D$23=A2), 1, TRUE), 3))
A15: Fairway Fighters | B15: 308 | C15: 108 | D15: 97
A16: Home Boys | B16: 213 | C16: 90 | D16: 86
A17: Tee Stingers | B17: 236 | C17: 87 | D17: 86
A18: Tee Titans | B18: 186 | C18: 86 | D18: 76
A19: Birdie Buddies | B19: 238 | C19: 57 | D19: 94
A20: Tee Tigers | B20: 156 | C20: 63 | D20: 64 | G20: `

Sheet Akasia
A1: Name | B1: Strokes | C1: IPS | D1: LIV
A2: Trevor Meyer | B2: 90 | C2: 40 | D2: =VLOOKUP(Table5[[#This Row],[Name]],Table2[],13,FALSE) -> Fairway Fighters
A3: Arno Adonis | B3: 88 | C3: 36 | D3: =VLOOKUP(Table5[[#This Row],[Name]],Table2[],13,FALSE) -> Home Boys
A4: Winston Willemse | B4: 91 | C4: 36 | D4: =VLOOKUP(Table5[[#This Row],[Name]],Table2[],13,FALSE) -> Tee Stingers
A5: John Barker | B5: 86 | C5: 36 | D5: =VLOOKUP(Table5[[#This Row],[Name]],Table2[],13,FALSE) -> Tee Tigers
A6: Ashley Spocter | B6: 93 | C6: 35 | D6: =VLOOKUP(Table5[[#This Row],[Name]],Table2[],13,FALSE) -> Tee Tigers
A7: Lucien Barnes | B7: 96 | C7: 35 | D7: =VLOOKUP(Table5[[#This Row],[Name]],Table2[],13,FALSE) -> Fairway Fighters
A8: Jodi Van Niekerk | B8: 89 | C8: 35 | D8: =VLOOKUP(Table5[[#This Row],[Name]],Table2[],13,FALSE) -> Tee Stingers
A9: Fuad Adams | B9: 93 | C9: 34 | D9: =VLOOKUP(Table5[[#This Row],[Name]],Table2[],13,FALSE) -> Home Boys
A10: Warren Lottering | B10: 97 | C10: 33 | D10: =VLOOKUP(Table5[[#This Row],[Name]],Table2[],13,FALSE) -> Tee Stingers
A11: Mika Moerat | B11: 87 | C11: 33 | D11: =VLOOKUP(Table5[[#This Row],[Name]],Table2[],13,FALSE) -> Fairway Fighters
A12: Dale Adonis | B12: 92 | C12: 32 | D12: =VLOOKUP(Table5[[#This Row],[Name]],Table2[],13,FALSE) -> Home Boys
A13: Godfrey Daniels | B13: 99 | C13: 31 | D13: =VLOOKUP(Table5[[#This Row],[Name]],Table2[],13,FALSE) -> Tee Tigers
... A23: Pieter Gagiano | B23: 112 | C23: 14 | D23: =VLOOKUP(Table5[[#This Row],[Name]],Table2[],13,FALSE) -> Tee Tigers
D24: =VLOOKUP(Table5[[#This Row],[Name]],Table2[],13,FALSE) -> #N/A

Sheet PGC
A1: Name | B1: Strokes | C1: IPS | D1: LIV
A2: Chad Naude | B2: 87 | C2: 35 | D2: =VLOOKUP(Table58[[#This Row],[Name]],Table2[],13,FALSE) -> Fairway Fighters
A3: Bjorn Singh | B3: 90 | C3: 35 | D3: =VLOOKUP(Table58[[#This Row],[Name]],Table2[],13,FALSE) -> Birdie Buddies
A4: Mika Moerat | B4: 81 | C4: 35 | D4: =VLOOKUP(Table58[[#This Row],[Name]],Table2[],13,FALSE) -> Fairway Fighters
A5: Arno Adonis | B5: 87 | C5: 32 | D5: =VLOOKUP(Table58[[#This Row],[Name]],Table2[],13,FALSE) -> Home Boys
A6: Lucien Barnes | B6: 96 | C6: 32 | D6: =VLOOKUP(Table58[[#This Row],[Name]],Table2[],13,FALSE) -> Fairway Fighters | F6: =SUM(C3:C5) -> 102
A7: Jodi Van Niekerk | B7: 91 | C7: 31 | D7: =VLOOKUP(Table58[[#This Row],[Name]],Table2[],13,FALSE) -> Tee Stingers
A8: Shawn Davies | B8: 82 | C8: 31 | D8: =VLOOKUP(Table58[[#This Row],[Name]],Table2[],13,FALSE) -> Birdie Buddies
A9: Lenny Booysen | B9: 106 | C9: 30 | D9: =VLOOKUP(Table58[[#This Row],[Name]],Table2[],13,FALSE) -> Tee Tigers | F9: =SUM(C7:C9) -> 92
A10: Trevor Meyer | B10: 95 | C10: 30 | D10: =VLOOKUP(Table58[[#This Row],[Name]],Table2[],13,FALSE) -> Fairway Fighters
A11: Laurent Changuion | B11: 93 | C11: 29 | D11: =VLOOKUP(Table58[[#This Row],[Name]],Table2[],13,FALSE) -> Tee Stingers
A12: Byron Labuschagne | B12: 94 | C12: 28 | D12: =VLOOKUP(Table58[[#This Row],[Name]],Table2[],13,FALSE) -> Birdie Buddies
A13: Dale Adonis | B13: 95 | C13: 27 | D13: =VLOOKUP(Table58[[#This Row],[Name]],Table2[],13,FALSE) -> Home Boys | F13: =SUM(C10:C12) -> 87
A14: Eugene Dudley | B14: 100 | C14: 27 | D14: =VLOOKUP(Table58[[#This Row],[Name]],Table2[],13,FALSE) -> Home Boys
A15: Warren Lottering | B15: 101 | C15: 26 | D15: =VLOOKUP(Table58[[#This Row],[Name]],Table2[],13,FALSE) -> Tee Stingers
A16: Ashley Spocter | B16: 102 | C16: 23 | D16: =VLOOKUP(Table58[[#This Row],[Name]],Table2[],13,FALSE) -> Tee Tigers
A17: Ranzel Louw | B17: 100 | C17: 22 | D17: =VLOOKUP(Table58[[#This Row],[Name]],Table2[],13,FALSE) -> Tee Tigers
A18: Pieter Gagiano | B18: 115 | C18: 22 | D18: =VLOOKUP(Table58[[#This Row],[Name]],Table2[],13,FALSE) -> Tee Tigers | F18: =SUM(C14:C16) -> 76
A19: Godfrey Daniels | B19: 108 | C19: 20 | D19: =VLOOKUP(Table58[[#This Row],[Name]],Table2[],13,FALSE) -> Tee Tigers
A20: Kirsten Jacobs | B20: 103 | C20: 23 | D20: =VLOOKUP(Table58[[#This Row],[Name]],Table2[],13,FALSE) -> Tee Tigers
A21: Winston Willemse | D21: =VLOOKUP(Table58[[#This Row],[Name]],Table2[],13,FALSE) -> Tee Stingers
A22: Fuad Adams | D22: =VLOOKUP(Table58[[#This Row],[Name]],Table2[],13,FALSE) -> Home Boys | F22: =SUM(C19:C21) -> 43
A23: Arn Smith | D23: =VLOOKUP(Table58[[#This Row],[Name]],Table2[],13,FALSE) -> Home Boys
A24: Dewald Van Rooyen | D24: =VLOOKUP(Table58[[#This Row],[Name]],Table2[],13,FALSE) -> Fairway Fighters | F24: =SUM(C23:C24) -> 0

Sheet Kyalami
A1: Name | B1: Strokes | C1: IPS | D1: LIV
A2: Chad Naude | B2: 90 | C2: 37 | D2: =VLOOKUP(Table585[[#This Row],[Name]],Table2[],13,FALSE) -> Fairway Fighters
A3: Arno Adonis | B3: 83 | C3: 37 | D3: =VLOOKUP(Table585[[#This Row],[Name]],Table2[],13,FALSE) -> Home Boys
A4: Warren Lottering | B4: 93 | C4: 36 | D4: =VLOOKUP(Table585[[#This Row],[Name]],Table2[],13,FALSE) -> Tee Stingers
A5: Lucien Barnes | B5: 95 | C5: 35 | D5: =VLOOKUP(Table585[[#This Row],[Name]],Table2[],13,FALSE) -> Fairway Fighters
A6: Bjorn Singh | B6: 93 | C6: 34 | D6: =VLOOKUP(Table585[[#This Row],[Name]],Table2[],13,FALSE) -> Birdie Buddies
A7: Dewald Van Rooyen | B7: 94 | C7: 31 | D7: =VLOOKUP(Table585[[#This Row],[Name]],Table2[],13,FALSE) -> Fairway Fighters
A8: Mika Moerat | B8: 90 | C8: 29 | D8: =VLOOKUP(Table585[[#This Row],[Name]],Table2[],13,FALSE) -> Fairway Fighters
A9: Ranzel Louw | B9: 93 | C9: 29 | D9: =VLOOKUP(Table585[[#This Row],[Name]],Table2[],13,FALSE) -> Tee Tigers
A10: Shaheen Boughan | B10: 95 | C10: 28 | D10: =VLOOKUP(Table585[[#This Row],[Name]],Table2[],13,FALSE) -> Birdie Buddies
A11: Jodi Van Niekerk | B11: 99 | C11: 27 | D11: =VLOOKUP(Table585[[#This Row],[Name]],Table2[],13,FALSE) -> Tee Stingers
A12: Byron Labuschagne | B12: 94 | C12: 25 | D12: =VLOOKUP(Table585[[#This Row],[Name]],Table2[],13,FALSE) -> Birdie Buddies
A13: Ashley Spocter | B13: 104 | C13: 24 | D13: =VLOOKUP(Table585[[#This Row],[Name]],Table2[],13,FALSE) -> Tee Tigers

Sheet CopperLeaf
A1: Name | B1: Strokes | C1: IPS | D1: LIV | E1: Handicap | F1: NP1 | G1: NP2 | H1: LD1 | I1: LD2 | J1: BG | K1: BN | L1: Pool Bet | M1: Pool Payouts | N1: Fines
A2: John Barker | B2: 80 | C2: 38 | D2: =VLOOKUP(Table58549[[#This Row],[Name]],Table2[],13,FALSE) -> Tee Tigers | E2: 11 | I2: 11 | K2: =Table58549[[#This Row],[Strokes]]-Table58549[[#This Row],[Handicap]] -> 69 | L2: X | N2: 20
A3: Arno Adonis | B3: 85 | C3: 34 | D3: =VLOOKUP(Table58549[[#This Row],[Name]],Table2[],13,FALSE) -> Home Boys | E3: 10 | K3: =Table58549[[#This Row],[Strokes]]-Table58549[[#This Row],[Handicap]] -> 75 | L3: X | N3: 20
A4: Ronny Kaptein | B4: 88 | C4: 34 | D4: =VLOOKUP(Table58549[[#This Row],[Name]],Table2[],13,FALSE) -> Tee Tigers | E4: 14 | H4: 6 | K4: =Table58549[[#This Row],[Strokes]]-Table58549[[#This Row],[Handicap]] -> 74 | L4: X | N4: 20
A5: Shawn Davies | B5: 79 | C5: 32 | D5: =VLOOKUP(Table58549[[#This Row],[Name]],Table2[],13,FALSE) -> Birdie Buddies | E5: 4 | K5: =Table58549[[#This Row],[Strokes]]-Table58549[[#This Row],[Handicap]] -> 75 | L5: X | N5: 20
A6: Winston Willemse | B6: 94 | C6: 32 | D6: =VLOOKUP(Table58549[[#This Row],[Name]],Table2[],13,FALSE) -> Tee Stingers | E6: 18 | K6: =Table58549[[#This Row],[Strokes]]-Table58549[[#This Row],[Handicap]] -> 76 | L6: X | N6: 20
A7: Lucien Barnes | B7: 99 | C7: 30 | D7: =VLOOKUP(Table58549[[#This Row],[Name]],Table2[],13,FALSE) -> Fairway Fighters | E7: 21 | K7: =Table58549[[#This Row],[Strokes]]-Table58549[[#This Row],[Handicap]] -> 78 | L7: X | N7: 20
A8: Pieter Gagiano | B8: 112 | C8: 30 | D8: =VLOOKUP(Table58549[[#This Row],[Name]],Table2[],13,FALSE) -> Tee Tigers | E8: 32 | K8: =Table58549[[#This Row],[Strokes]]-Table58549[[#This Row],[Handicap]] -> 80 | L8: X | N8: 20
A9: Mika Moerat | B9: 87 | C9: 28 | D9: =VLOOKUP(Table58549[[#This Row],[Name]],Table2[],13,FALSE) -> Fairway Fighters | E9: 7 | K9: =Table58549[[#This Row],[Strokes]]-Table58549[[#This Row],[Handicap]] -> 80 | L9: X | N9: 20
A10: Dale Adonis | B10: 93 | C10: 26 | D10: =VLOOKUP(Table58549[[#This Row],[Name]],Table2[],13,FALSE) -> Home Boys | E10: 14 | F10: 5 | K10: =Table58549[[#This Row],[Strokes]]-Table58549[[#This Row],[Handicap]] -> 79 | L10: X | N10: 20
A11: Laurent Changuion | B11: 90 | C11: 25 | D11: =VLOOKUP(Table58549[[#This Row],[Name]],Table2[],13,FALSE) -> Tee Stingers | E11: 8 | K11: =Table58549[[#This Row],[Strokes]]-Table58549[[#This Row],[Handicap]] -> 82 | L11: X | N11: 20
A12: Shaheen Boughan | B12: 96 | C12: 24 | D12: =VLOOKUP(Table58549[[#This Row],[Name]],Table2[],13,FALSE) -> Birdie Buddies | E12: 11 | G12: 14 | K12: =Table58549[[#This Row],[Strokes]]-Table58549[[#This Row],[Handicap]] -> 85 | L12: X | N12: 20
A13: Eugene Dudley | B13: 104 | C13: 24 | D13: =VLOOKUP(Table58549[[#This Row],[Name]],Table2[],13,FALSE) -> Home Boys | E13: 22 | K13: =Table58549[[#This Row],[Strokes]]-Table58549[[#This Row],[Handicap]] -> 82 | L13: X | N13: 20
A14: Jodi Van Niekerk | B14: 100 | C14: 24 | D14: =VLOOKUP(Table58549[[#This Row],[Name]],Table2[],13,FALSE) -> Tee Stingers | E14: 15 | K14: =Table58549[[#This Row],[Strokes]]-Table58549[[#This Row],[Handicap]] -> 85 | L14: X | N14: 20
A15: Trevor Meyer | B15: 110 | C15: 18 | D15: =VLOOKUP(Table58549[[#This Row],[Name]],Table2[],13,FALSE) -> Fairway Fighters | E15: 19 | K15: =Table58549[[#This Row],[Strokes]]-Table58549[[#This Row],[Handicap]] -> 91 | L15: X | N15: 20
A16: Ranzel Louw | B16: 102 | C16: 16 | D16: =VLOOKUP(Table58549[[#This Row],[Name]],Table2[],13,FALSE) -> Tee Tigers | E16: 10 | K16: =Table58549[[#This Row],[Strokes]]-Table58549[[#This Row],[Handicap]] -> 92 | L16: X | N16: 20

Sheet Services
A1: Name | B1: Strokes | C1: IPS | D1: LIV | E1: Handicap | F1: NP1 | G1: NP2 | H1: LD1 | I1: LD2 | J1: BG | K1: BN | L1: Pool Bet | M1: Pool Payouts | N1: Fines
A2: John Barker | B2: 0 | C2: 0 | D2: =VLOOKUP(Table5854910[[#This Row],[Name]],Table2[],13,FALSE) -> Tee Tigers
A3: Arno Adonis | B3: 0 | C3: 0 | D3: =VLOOKUP(Table5854910[[#This Row],[Name]],Table2[],13,FALSE) -> Home Boys
